Workbook

Sheet 总结建议
B1: FSMP蛋白组件 | C1: 保健食品蛋白粉 | D1: 普通食品蛋白粉
A2: 医务渠道流通 | B2: 院采不受限 | C2: 院采受限 | D2: 院采受限
A3: 目标人群 | B3: 特定疾病或医学状况下需要补充蛋白质 | C3: 免疫力低下人群 | D3: 需要补充蛋白质的各类人群
A4: 应用场景 | B4: 老人成人术后补充 | C4: 亚健康人群、手术后痊愈者、中老年人群 | D4: 健身爱好者、白领女性等
A5: 产品宣称 | B5: 给疾病人群补充蛋白质 | C5: 提高免疫力 | D5: 补充蛋白质
A6: 竞品数量 | B6: 少 | C6: 多 | D6: 多
A7: FK现状 | B7: FSMP注册难，时间长 | C7: 需评估，比FSMP快 | D7: 可立即引入
A10: BUN推广Fresubin PROTEIN（保健食品）SWOT分析
A11: 优势 | B11: 1. 肾科医务资源丰富； 2. 肾科营养食品推广基础扎实； 3. 透析患者人群精准，可覆盖； 4. 产品蛋白含量（87%）高于康比特、汤臣倍健、 安利纽崔莱等TOP品牌产品； 5. 产品除常规罐装外，设有袋装，较大多罐装保健食 品，方便携带，且2个SKU利于分渠道差异化推广； 6. 蛋白粉+费瑞卡，可实现透析患者蛋白、能量摄入 平衡，有产品组合优势。 | D11: 劣势 | E11: 1. 产品同质化严重，无明显特性区分，配方 需按起始目标人群-透析患者需求做特殊调整； 2. 产品开发速度跟不上阶梯推广需求； 3. 营养食品推广代表精力有限，很难完美兼顾 处方药、食品、保健食品、特医的同步推广； 4. 现有商务体系不适配保健食品渠道铺货及 价格维护，有巨大的价格管理挑战； 5. 线下终端（药店、商超）是蛋白粉类保健食 品有利的推广渠道之一，现有销售团队缺乏有 效的、系统的终端合作模式； 6. 线上终端（传统电商、外卖平台）是蛋白粉 类保健食品有利的推广渠道之一，现有市场销 售人员配置无法利用平台营销；
A12: 机会 | B12: 1. 蛋白质市场成熟，教育成本低； 2. 蛋白粉需求量大，人群多； 3. 蛋白粉长期、大量消耗人群之一——健身人士， 逐渐关注肾脏健康；中老年人群，同样关注肾脏健康； 4. FK当前覆盖的透析患者，有汤臣倍健蛋白粉消费倾 向，可直接转化； 5. 从透析患者入手，品牌定位从“透析患者适用” 到“透析病人严选”，进行阶梯式推广，目标人群以 “透析患者”为起点，逐步扩大到“中老年人群”和 “健身人群”。 | D12: 威胁 | E12: 1. 若特定疾病非全营养FSMP蛋白类产品面世， 则医务推广难度增加； 2. 蛋白粉保健品市场竞争激烈，竞品有多年消 费者端推广经验，且与各零售渠道有着良好的 合作基础，远胜于FK； 3. 蛋白粉固体饮料有更丰富的口味，且被允许 添加和标识多种营养素，产品优势更佳。
A14: 阶梯推广策略
A15: 目标人群 | B15: 透析患者 | C15: 术后患者 | D15: 中老年人群 | E15: 健身人群
A16: 人群需求 | B16: 提升蛋白 | C16: 加速康复 | D16: 增强免疫，保持肌肉 | E16: 增长肌肉
A17: 推广点 | B17: 100%乳清蛋白，低磷低钾 | C17: 100%乳清蛋白，好消化，好吸收 | D17: 100%乳清蛋白，好消化，好吸收，透析患者严选，肾脏友好 | E17: 100%乳清蛋白，透析患者严选，肾脏友好
A18: 推广方式 | B18: BUN医务推广 | C18: BUN+PN/EN/FSMP医务推广 | D18: 电商推广+社区推广 | E18: 电商推广+特渠推广（健身房）
A19: 产品推广组合 | B19: PROTEIN+费瑞卡，蛋白能量平衡，预防PEW（蛋白能量消耗） | C19: 优选德瑞太，嫌贵选PROTEIN | D19: 优选德瑞康，嫌贵选PROTEIN 抢汤臣倍健用户
A21: 产品升级策略
A22: 目标人群 | B22: 透析患者 | C22: 术后患者 | D22: 中老年人群 | E22: 健身人群
A23: 产品身份 | B23: 特医食品/保健食品 | C23: 特医食品/保健食品 | D23: 保健食品/普通食品 | E23: 普通食品-运动食品
A24: 配方 | B24: PROTEIN+胆碱+肌醇+牛磺酸+左旋肉碱….-磷-钾 | C24: PROTEIN+胆碱+肌醇+牛磺酸+左旋肉碱….-磷-钾 | D24: PROTEIN+胆碱+肌醇+牛磺酸+左旋肉碱….-磷-钾+钙【高钙版】 | E24: PROTEIN+胆碱+肌醇+牛磺酸+左旋肉碱….-磷-钾+氨糖【软骨呵护版】
D25: PROTEIN+胆碱+肌醇+牛磺酸+左旋肉碱….-磷-钾+钙+益生菌【胃肠道舒适版】
A26: 透析、术后患者需与医学沟通确认，普通食品配方建议原则为：特医食品/保健食品基础配方+特殊营养素

Sheet 市售产品
A1: 品牌 | B1: 企业 | C1: 大陆流通身份 | D1: 产品名称 | E1: 企业名称 | F1: 适用人群 | G1: 规格 | H1: 官方建议零售价（元） | I1: 每1g价格 | J1: 每100g价格 | K1: 蛋白纯度 | L1: 每g蛋白价格 | M1: 磷含量mg /100g | N1: 钾含量mg /100g | O1: 磷含量mg /100g蛋白 | P1: 钾含量mg /100g蛋白 | Q1: 目标人群及使用场景推广 | R1: 配料 | S1: 标准冲调 | T1: 标准冲调液渗透压 | U1: 保质期 | V1: 每日推荐摄入量 | W1: 法规宣称 | X1: 渠道
X2: 医院 | Y2: 药店 | Z2: 京东 | AA2: 淘宝 | AB2: 小红书 | AC2: 抖音 | AD2: 自营-小程序
A3: 伊能佳 | C3: 已获批蛋白质（氨基酸）组件 | D3: 伊能佳®特殊医学用途蛋白质组件配方食品 | E3: 浙江海正甦力康生物科技有限公司 | F3: 10岁以上特定疾病或医学状况下需要补充蛋白质的人群。 | G3: 280g/罐 | H3: 498 | I3: =J3/100 -> 1.7785714 | J3: =H3/280*100 -> 177.85714 | K3: 0.773 | L3: =J3/K3/100 -> 2.3008686 | Q3: 老人成人术后补充 | R3: 乳清蛋白粉、大豆分离蛋白 | S3: 150mL温开水+20g | T3: 51~61mOsm/kg | U3: 24个月 | V3: 在医生或临床营养师指导下根据适用人群个体情况或医学状况综合确定 | Z3: 有 | AA3: 有
G4: 240g/盒（20g*12袋） | H4: 468 | I4: =J4/100 -> 1.95 | J4: =H4/240*100 -> 195 | K4: 0.773 | L4: =J4/K4/100 -> 2.5226391
A5: 普柔汀 | C5: 已获批蛋白质（氨基酸）组件 | D5: 普柔汀®特殊医学用途蛋白质组件配方食品 | E5: 广州纽健生物科技有限公司 | F5: 10岁以上特定疾病或医学状况下需要补充蛋白质的人群。 | G5: 144g/盒（12g*12袋） | H5: 698 | I5: =J5/100 -> 4.8472222 | J5: =H5/144*100 -> 484.72222 | K5: 0.87 | L5: =J5/K5/100 -> 5.5715198 | R5: 浓缩乳清蛋白粉、大豆分离蛋白、瓜尔胶、罗汉果甜苷 | S5: 60mL温开水（低于40℃）+12g | T5: 90mOsm/L | U5: 12个月 | AD5: 有
A6: 浦索 | C6: 已获批蛋白质（氨基酸）组件 | D6: 浦索®特殊医学用途蛋白质组件配方粉 | E6: 吉林麦孚营养科技有限公司长春分公司 | F6: 10岁以上特定疾病或医学状况下需要补充蛋白质的人群。 | G6: 225g/盒（7.5g*30袋） | H6: 399 | I6: =J6/100 -> 1.7733333 | J6: =H6/225*100 -> 177.33333 | K6: 0.87 | L6: =J6/K6/100 -> 2.0383142 | R6: 分离乳清蛋白粉、酪蛋白酸钙、食用香精、磷脂、三氯蔗糖 | S6: 60mL温开水（40-45℃）+7.5g | T6: 45mOsmol/kg | U6: 24个月 | V6: 在医生或临床营养师指导下根据适用人群个体情况或医学状况综合确定
C7: 已获批蛋白质（氨基酸）组件 | G7: 135g/盒（7.5g*18袋） | H7: 270 | I7: =J7/100 -> 2 | J7: =H7/135*100 -> 200 | K7: 0.87 | L7: =J7/K7/100 -> 2.2988506 | AA7: 有
A8: 冬泽定 | C8: 已获批蛋白质（氨基酸）组件 | D8: 冬泽定®特殊医学用途蛋白质组件配方食品 | E8: 湖南九典制药股份有限公司 | F8: 10岁以上特定疾病或医学状况下需要补充蛋白质的人群。 | G8: 180g/盒（15g*12袋） | H8: 498 | I8: =J8/100 -> 2.7666667 | J8: =H8/180*100 -> 276.66667 | K8: 0.8 | L8: =J8/K8/100 -> 3.4583333 | R8: 水解乳清蛋白粉、大豆肽粉、食用香精、甜菊糖苷、三氯蔗糖 | S8: 100mL温开水（40-45℃）+15g | T8: 75mOsmol/kg | U8: 24个月 | V8: 根据适用人群年龄、体重和医学状况等综合确定 | Z8: 有 | AA8: 有 | AD8: 有
A9: 舒畅 | C9: 已获批蛋白质（氨基酸）组件 | D9: 舒畅®特殊医学用途蛋白质组件配方食品 | E9: 江西人之初乳品营养有限公司 | F9: 10岁以上特定疾病或医学状况下需要补充蛋白质的人群。 透析患者。 | G9: 192g/盒（12g*16袋） | H9: 458 | I9: =J9/100 -> 2.3854167 | J9: =H9/192*100 -> 238.54167 | K9: 0.86 | L9: =J9/K9/100 -> 2.7737403 | M9: =186*K9 -> 159.96 | N9: 14 | O9: =M9/$K9 -> 186 | P9: =N9/$K9 -> 16.27907 | Q9: 透析人群 | R9: 分离乳清蛋白、酪蛋白 | S9: 60mL+12g | X9: 有
A10: 康比特 | C10: 保健食品注册 | D10: 康比特牌酵母葡聚糖乳清蛋白粉 | E10: 北京康比特体育科技股份有限公司 | F10: 免疫力低下人群 | G10: 400g/罐 | H10: 229 | I10: =J10/100 -> 0.5725 | J10: =H10/400*100 -> 57.25 | K10: 0.56 | L10: =J10/K10/100 -> 1.0223214 | Q10: 亚健康人群、手术后痊愈者、中老年人群 | R10: 浓缩乳清蛋白、分离乳清蛋白粉、酵母β-葡聚糖 | S10: 60mL温开水+10g（1勺） | U10: 24个月 | V10: 1次（10g） | W10: 保健功能：增强免疫力 | Z10: 有 | AA10: 有 | AB10: 有 | AC10: 有 | AD10: 有
A11: 汤臣倍健 | C11: 保健食品注册 | D11: 汤臣倍健蛋白粉 | E11: 汤臣倍健股份有限公司 | F11: 免疫力低下人群 | G11: 450g/罐+150g/罐 | H11: 421 | I11: =J11/100 -> 0.70166667 | J11: =H11/600*100 -> 70.166667 | K11: 0.8 | L11: =J11/K11/100 -> 0.87708333 | Q11: 亚健康人群、银发族、术后营养 | R11: 大豆分离蛋白、浓缩乳清蛋白、大豆磷脂 | S11: 200mL温开水（40℃左右）+10g（1勺） | U11: 24个月 | V11: 1次（10g） | W11: 保健功能：增强免疫力 | Z11: 有 | AA11: 有 | AB11: 有 | AC11: 有 | AD11: 有
A12: 纽崔莱 | C12: 保健食品注册 | D12: 安利Amway纽崔莱多种植物蛋白粉 | E12: 安利(中国)日用品有限公司官方 | F12: 免疫力低下者、易疲劳者 | G12: 770g/瓶 | H12: 560 | I12: =J12/100 -> 0.72727273 | J12: =H12/770*100 -> 72.727273 | K12: 0.8 | L12: =J12/K12/100 -> 0.90909091 | Q12: 工作压力大、疲惫、超负荷人群 | R12: 大豆分离蛋白（大豆分离蛋白、磷脂）、小麦蛋白、豌豆蛋白 | S12: 加入水或牛奶 | U12: 24个月 | V12: 1次（10g） | W12: 保健功能：增强免疫力 | AD12: 有
A13: 谱元泰 | C13: 保健食品注册 | D13: 谱元泰乳清蛋白粉 | E13: 北京康百世科技发展有限公司 | F13: 成人、中老年人 | G13: 500g/罐 | H13: 618 | I13: 1.23 | J13: 123 | K13: 0.9 | L13: =J13/K13/100 -> 1.3666667 | Q13: 运动员、蛋白质摄入不足者、术前术后患者、老年人、孕产妇、儿童青少年等需要额外补充蛋白质的人群 | R13: 分离乳清蛋白粉、鹰嘴豆粉 | S13: 50ml适量温开水（40℃左右）或温牛奶或果汁+10g（1勺） | U13: 24个月 | V13: 2次（20g） | Z13: 有 | AA13: 有 | AC13: 有 | AD13: 有
A14: 康比特 | C14: 普通食品 | D14: 康比特酸奶乳清（CPTpro®） | E14: 北京康比特体育科技股份有限公司 | F14: 需要补充蛋白质的各类人群 | G14: 300g/瓶 | H14: 98 | I14: =J14/100 -> 0.32666667 | J14: =H14/300*100 -> 32.666667 | K14: 0.75 | L14: =J14/K14/100 -> 0.43555556 | Q14: 健身爱好者：减控雕塑线条、日常蛋白补充、日常运动 | R14: CPTpro®乳清蛋白混合粉（浓缩乳清蛋白、维生素D、黑胡椒提取物）、脱脂风味酸乳发酵粉、磷酸三钙、牛磺酸、灭活型乳酸菌粉（植物乳植杆菌、副干酪乳酪杆菌、罗伊氏粘液乳杆菌、鼠李糖乳酪杆菌、发酵粘液乳杆菌）、硫酸锌、维生素A、维生素B1、维生素B2、维生素B6、黄原胶、安赛蜜、柠檬酸、阿斯巴甜（含苯丙氨酸）、食品用香精 | S14: 180mL水或牛奶+30g（2勺） | U14: 24个月 | V14: 1次（30g） | Z14: 有 | AA14: 有 | AB14: 有 | AC14: 有 | AD14: 有
A15: Swisse | C15: 固体饮料 | D15: Swisse斯维诗乳清蛋白粉（香草味） | E15: 合生元（长沙）营养食品有限公司 | F15: 需要补充蛋白质的各类人群 | G15: 450g/罐 | H15: 269 | I15: =J15/100 -> 0.59777778 | J15: =H15/450*100 -> 59.777778 | K15: 0.753 | L15: =J15/K15/100 -> 0.79386159 | Q15: 独立女性：运动女性、白领女性、追求好状态女性 | R15: 浓缩乳清蛋白粉（浓缩乳清蛋白、磷脂）、香草香精 | S15: 100-150mL水或牛奶+1勺 | V15: 1-2次 | Z15: 有 | AA15: 有 | AB15: 有 | AC15: 有 | AD15: 有
A16: MYPROTEIN | C16: 跨境 | D16: MYPROTEIN IMPACT乳清蛋白粉（原味） | F16: 健身人士 | G16: 2.5kg/袋 | H16: 520 | I16: =J16/100 -> 0.208 | J16: =H16/2500*100 -> 20.8 | K16: 0.82 | L16: =J16/K16/100 -> 0.25365854 | Q16: 训练没精神、身体瘦弱 | R16: 浓缩乳清蛋白（牛奶）、乳化剂（大豆卵磷脂，向日葵卵磷脂） | S16: 150-250mL水或牛奶+25g（1勺） | U16: 18个月 | V16: 1次（25g） | Z16: 有 | AA16: 有 | AC16: 有
A17: 考尔夫 | C17: 普通食品 | D17: 考尔夫透析蛋白粉 | E17: 中恩（天津）医药有限公司 | F17: 需要补充蛋白质的各类人群 | G17: 500g/罐（20g*25袋） | H17: 238 | I17: 0.48 | J17: 47.6 | K17: 0.205 | L17: =J17/K17/100 -> 2.3219512 | Q17: 体质弱、中老年、运动健身、需高蛋白控水控磷人群、儿童和青少年 | R17: 分离乳清蛋白 | S17: 50ml温水（55-60℃）+1袋 | U17: 18个月 | V17: 1次（1-2袋/20-40g） | Z17: 有
A18: 乐析能 | C18: 普通食品 | D18: 乐析能透析蛋白粉 | E18: 台湾丰世纪股份有限公司 | F18: 术后恢复、中老年人、透友人群以及进食受限，消化吸收障碍，代谢紊乱需要补充营养的人群 | G18: 240g/盒（20g*12袋） | H18: 258 | I18: 1.07 | J18: 107.5 | K18: 0.223 | L18: =J18/K18/100 -> 4.8206278 | Q18: 术后恢复、中老年人、透友人群以及进食受限，消化吸收障碍，代谢紊乱需要补充营养的人群 | S18: 50-60ml温水（60℃）+20g（1包） | U18: 24个月 | V18: 2次（2袋40g） | Z18: 有 | AA18: 有 | AB18: 有 | AC18: 有 | AD18: 有
A19: 纽特舒玛 | C19: 普通食品 | D19: 纽特舒玛分离乳清蛋白质固体饮料营养粉 | E19: Nutrasumma,Inc. | F19: 术后、化疗、肠胃脆弱、身体弱、糖友 | G19: 464g/罐 | H19: 598 | I19: =H19/464 -> 1.2887931 | J19: =I19*100 -> 128.87931 | K19: 0.862 | L19: =J19/K19/100 -> 1.4951196 | M19: =营养成分对比!U18 -> 250 | N19: =营养成分对比!U17 -> 339.65517 | O19: =M19/$K19 -> 290.0232 | P19: =N19/$K19 -> 394.03152 | Q19: 术后、化疗、肠胃脆弱、身体弱、糖友 | R19: 分离乳清蛋白粉、磷脂 | S19: 200ml温水（≤30℃）+23.2g(1勺) | U19: 36个月 | Z19: 有 | AA19: 有 | AB19: 有 | AC19: 有 | AD19: 有
A20: 圣安多 | C20: 普通食品 | D20: 圣安多蛋白质固体饮料 | E20: 仙乐健康科技股份有限公司 | F20: 肾病透析专用蛋白粉 | G20: 180g/盒 | H20: 258 | I20: =H20/180 -> 1.4333333 | J20: =I20*100 -> 143.33333 | K20: 0.8 | L20: =J20/K20/100 -> 1.7916667 | M20: =营养成分对比!V18 -> 90 | N20: =营养成分对比!V17 -> 20 | O20: =M20/$K20 -> 112.5 | P20: =N20/$K20 -> 25 | Q20: 肾病透析专用蛋白粉 | R20: 分离乳清蛋白粉,低聚异麦芽糖(0.5g/袋),麦芽糊精,大豆肤粉,低聚果糖(0.2g/袋),维生素B6,中链甘油三醋微囊粉 (固体饮料),苹果西袖粉,食品用香精，二氧化硅,干酪乳酪杆菌(灭活型) | S20: 30ml-100ml温水+1袋（10g） | U20: 24个月 | V20: 1-3次 | Z20: 有
A21: 威高 | C21: 普通食品 | D21: 威高分离乳清蛋白粉 | E21: 威海紫光优健科技股份有限公司 | F21: 透析、体质弱亚健康等需优质蛋白补充人群、围手术期、限钾限磷 | G21: 200g/盒 | H21: 156 | I21: =H21/200 -> 0.78 | J21: =I21*100 -> 78 | K21: 0.86 | L21: =J21/K21/100 -> 0.90697674 | M21: =营养成分对比!W18 -> 24 | N21: =营养成分对比!W17 -> 21 | O21: =M21/$K21 -> 27.906977 | P21: =N21/$K21 -> 24.418605 | Q21: 透析、体质弱亚健康等需优质蛋白补充人群、围手术期、限钾限磷 | R21: 分离乳清蛋白(添加量:9.5g/10g)、结晶果糖、异麦芽酮糖、食品用香精、安赛蜜、胆钙化醇(维生素D3) | S21: 30-50ml温水（40-60℃）+1袋（10g） | U21: 24个月 | V21: 1-4次 | Z21: 有 | AA21: 有 | AD21: 有
A22: 析安能 | C22: 普通食品 | D22: 析安能乳清蛋白粉固体饮料 | E22: 上海世康特制药有限公司 | F22: 肾友透析蛋白粉 | G22: 500g/罐（20g*25袋） | H22: 268 | I22: =H22/500 -> 0.536 | J22: =I22*100 -> 53.6 | K22: 0.21 | L22: =J22/K22/100 -> 2.552381 | Q22: 肾友透析 | S22: 60ml温水（45℃）+1袋（20g） | U22: 18个月 | V22: 1-2次 | Z22: 有 | AA22: 有
A23: 领透析尔舒 | C23: 普通食品 | D23: 领透析尔舒乳清蛋白粉固体饮料 | E23: 上海世康特制药有限公司 | F23: 肾友透析蛋白粉 | G23: 300g/盒（10g*30袋） | H23: 319 | I23: =H23/300 -> 1.0633333 | J23: =I23*100 -> 106.33333 | K23: 0.8 | L23: =J23/K23/100 -> 1.3291667 | M23: =营养成分对比!AA18 -> 0 | N23: =营养成分对比!AA17 -> 0 | O23: =M23/$K23 -> 0 | P23: =N23/$K23 -> 0 | Q23: 肾友透析 | R23: 分离乳清蛋白(添加量≥80%)结晶果糖粉。复合维生素(L-抗坏血酸，β-胡萝卜素，烟酸，D-泛酸钙，核黄素，烟酸硫胺素，烟酸吡哆醇，叶酸，牛磺酸)，复合矿物质（硫酸亚铁，葡萄糖酸锌)，食用香精 | S23: 40-50ml温水（45℃）+1袋（10g） | Z23: 有
A24: 蛋百乐 | C24: 普通食品 | D24: 蛋百乐乳清蛋白粉固体饮料 | E24: 北京费森尤斯卡比 | F24: 透析、老年、术后人群 | G24: 440g/听（11g*40次） | H24: 528 | I24: =H24/440 -> 1.2 | J24: =I24*100 -> 120 | K24: 0.92 | L24: =J24/K24/100 -> 1.3043478 | M24: 26 | N24: 21 | O24: =M24/$K24 -> 28.26087 | P24: =N24/$K24 -> 22.826087 | Q24: 院内住院人群：院内配制，处方 透析+老年+术后：补充蛋白，增强免疫，加速康复 | R24: 速溶分离乳清蛋白(乳清、磷脂)、抗性糊精。 | U24: 24个月 | V24: 1.5-3勺（11-22g粉,10-20g蛋白） | W24: 无
F25: 需要补充蛋白质的各类人群(透析、老年、健身、女性） | G25: 330g/盒（11g*30袋） | H25: 428 | I25: =H25/330 -> 1.2969697 | J25: =I25*100 -> 129.69697 | K25: 0.92 | L25: =J25/K25/100 -> 1.4097497 | M25: 36 | N25: 33 | O25: =M25/$K25 -> 39.130435 | P25: =N25/$K25 -> 35.869565 | Q25: 蛋白粉消费人群(透析、老年、健身、女性）：肌肉增长/修复，提高免疫 | V25: 1-2袋（11-22g粉,10-20g蛋白） | W25: 无
L26: =L25-L24 -> 0.10540184

Sheet 营养成分对比
B1: FSMP | L1: 保健食品 | P1: 普通食品 | AB1: 普通食品 | AE1: 普通食品
A2: 品牌名称 | B2: 伊能佳 | D2: 普柔汀 | F2: 浦索 | H2: 冬泽定 | J2: 舒畅 | L2: 康比特 | M2: 汤臣倍健 | N2: 安利 | O2: 谱元素分离乳清蛋白粉 | P2: 康比特酸奶乳清 | Q2: Swisse | R2: MYPROTEIN | S2: 考尔夫 | T2: 乐析能 | U2: 纽特舒玛 | V2: 圣安多 | W2: 威高乳清蛋白粉 | X2: 析安能（条装） | Y2: 析安能（罐装） | Z2: 析尔舒 | AA2: 冬泽力 | AB2: 蛋百乐 | AE2: ProtiMedic AMINO Plus
A3: 企业名称
A4: 改企业其他在售产品品牌名称
A5: 适用/目标人群 | B5: 10岁以上特定疾病或医学状况下需要补充蛋白质的人群-老人成人术后补充 | J5: 10岁以上特定疾病或医学状况下需要补充蛋白质的人群-透析患者 | L5: 免疫力低下人群-亚健康人群、手术后痊愈者、中老年人群 | M5: 免疫力低下人群 | N5: 免疫力低下者、易疲劳者 | O5: 运动员、蛋白质摄入不足者、术前术后患者、老年人、孕产妇、儿童青少年等需要额外补充蛋白质的人群 | P5: 健身爱好者：减控雕塑线条、日常蛋白补充、日常运动 | Q5: 独立女性：运动女性、白领女性、追求好状态女性 | R5: 健身人士：训练没精神、身体瘦弱 | S5: 体质弱、中老年、运动健身、需高蛋白控水控磷人群、儿童和青少年 | T5: 术后恢复、中老年人、透友人群以及进食受限，消化吸收障碍，代谢紊乱需要补充营养的人群 | U5: 术后、化疗、肠胃脆弱、身体弱、糖友 | V5: 肾病透析专用蛋白粉 | W5: 透析、体质弱亚健康等需优质蛋白补充人群、围手术期、限钾限磷 | X5: 透析全营养粉 | Y5: 透析全营养粉 | Z5: 肾友透析蛋白粉 | AB5: 免疫力低下人群 透析患者→术后康复→中老年人群→健身人群 | AE5: 由于年龄导致的肌肉量下降，康复，肌肉减少症，癌症，心力衰竭，慢性阻塞性肺病，肝功能衰竭，严重疾病，伤口和压疮以及术前和术后人群，适用于成人及3岁以上儿童
A6: 营养成分 | B6: 每100g | C6: 每100kJ | D6: 每100g | E6: 每100kJ | F6: 每100g | G6: 每100kJ | H6: 每100g | I6: 每100kJ | J6: 每100g | K6: 每100kJ | L6: 每100g | M6: 每100g | N6: 每100g | O6: 每100g | P6: 每100g | Q6: 每100g | R6: 每100g | S6: 每100g | T6: 每100g | U6: 每100g | V6: 每100g | W6: 每100g | X6: 每100g | Y6: 每100g | Z6: 每100g | AA6: 每100g | AB6: 每100mL | AC6: 每100g | AD6: 每100kJ | AE6: 每40mL | AF6: 每100mL
A7: 价格（元）-罐装 | B7: =市售产品!J3 -> 177.85714 | F7: =市售产品!J6 -> 177.33333 | H7: =市售产品!J8 -> 276.66667 | L7: =市售产品!J10 -> 57.25 | M7: =市售产品!J11 -> 70.166667 | N7: =市售产品!J12 -> 72.727273 | O7: 123 | P7: =市售产品!J14 -> 32.666667 | Q7: =市售产品!J15 -> 59.777778 | R7: =市售产品!J16 -> 20.8 | U7: 113 | Y7: =268/500*100 -> 53.6
A8: 价格（元）-条装 | B8: =市售产品!J4 -> 195 | F8: =市售产品!J7 -> 200 | J8: =市售产品!J9 -> 238.54167 | S8: 48 | T8: 108 | V8: 140 | W8: 74 | X8: 50 | Z8: =319/300*100 -> 106.33333 | AA8: 398 | AE8: =71.4/50*7.8574 -> 11.220367
A9: 能量（kJ） | B9: 1578 | C9: 100 | F9: 1559 | G9: 100 | H9: 1380 | I9: 100 | O9: 1581 | P9: 1532 | Q9: 1695 | R9: 1740 | S9: 1864 | T9: 2157 | U9: 1599.12 | V9: 1580 | W9: 1586 | X9: 2041 | Y9: 1875 | Z9: 1589 | AA9: 1548 | AC9: 1602 | AD9: 100 | AE9: 335 | AF9: 837
A10: 能量（kcal） | AE10: 80 | AF10: 200
A11: 蛋白质（g） | B11: 77.3 | C11: 4.9 | F11: 87 | G11: 5.6 | H11: 80 | I11: 5.8 | J11: 86 | L11: 56 | M11: 80 | N11: 80 | O11: 90 | P11: 75 | Q11: 75.3 | R11: 82 | S11: 20.5 | T11: 22.3 | U11: 86.2 | V11: 80 | W11: 86 | X11: 15.2 | Y11: 21 | Z11: 80 | AA11: 90 | AC11: 92 | AD11: =100*AC11/AC$9 -> 5.7428215 | AE11: 20 | AF11: 50
A12: 脂肪（g） | B12: 3.7 | C12: 0.2 | F12: 1 | G12: 0.1 | H12: 0 | I12: 0 | O12: 0 | P12: 0.5 | Q12: 7.4 | R12: 7.5 | S12: 16.1 | T12: 26.1 | U12: 2.15 | V12: 4 | W12: 0 | X12: 17.6 | Y12: 17 | Z12: 0.9 | AA12: 0.2 | AC12: 0.9 | AD12: =100*AC12/AC$9 -> 0.056179775 | AE12: ＜0.1 | AF12: ＜0.1
A13: -饱和脂肪酸（g） | R13: 5 | AC13: 0.4 | AD13: =100*AC13/AC$9 -> 0.024968789
A14: -反式脂肪（g） | T14: 0 | X14: 0 | Y14: 0 | AC14: 0.02 | AD14: =100*AC14/AC$9 -> 0.0012484395
A15: 碳水化合物（g） | B15: 7.4 | C15: 0.5 | F15: 2.5 | G15: 0.2 | H15: 1.2 | I15: 0.1 | O15: 2.5 | P15: 14 | Q15: 8.3 | R15: 4 | S15: 51.5 | T15: 46 | U15: 2.59 | V15: 4 | W15: 7.3 | X15: 63.8 | Y15: 49 | Z15: 11.2 | AA15: 0.6 | AC15: 0.3 | AD15: =100*AC15/AC$9 -> 0.018726592 | AE15: 0 | AF15: 0
A16: 钠（mg） | B16: 268 | C16: 17 | F16: 110 | G16: 7 | H16: 1110 | I16: 80.4 | O16: 200 | P16: 135 | Q16: 361 | R16: 50 | S16: 128 | T16: 346 | U16: 362.07 | V16: 630 | W16: 579 | X16: 70 | Y16: 202 | Z16: 539 | AA16: 80 | AC16: 539 | AD16: =100*AC16/AC$9 -> 33.645443 | AE16: 117 | AF16: 293
A17: 钾（mg） | B17: 471 | C17: 30 | D17: 无标识 | F17: 无标识 | H17: 无标识 | J17: =市售产品!N9 -> 14 | O17: 400 | S17: 0 | T17: 222 | U17: =78.8/23.2*100 -> 339.65517 | V17: 20 | W17: 21 | X17: 160 | Y17: 0 | Z17: 32 | AC17: 33 | AD17: =100*AC17/AC$9 -> 2.0599251 | AE17: 13.1（7） | AF17: 33
A18: 磷（mg） | D18: 无标识 | F18: 无标识 | H18: 无标识 | J18: =市售产品!M9 -> 159.96 | O18: 220 | S18: 0 | T18: 142 | U18: =58/23.2*100 -> 250 | V18: 90 | W18: 24 | X18: 70 | Y18: 0 | Z18: 36 | AC18: 36 | AD18: =100*AC18/AC$9 -> 2.247191 | AE18: 160（54） | AF18: 400
A19: 钙（mg） | P19: 645 | T19: 255 | X19: 244 | Y19: 250 | AC19: 79 | AD19: =100*AC19/AC$9 -> 4.9313358 | AE19: 47 | AF19: 118
A20: 镁（mg） | S20: 144 | X20: 108 | Y20: 130 | AC20: 10 | AD20: =100*AC20/AC$9 -> 0.62421973 | AE20: 2.5 | AF20: 6.25
A21: 限制氨基酸评分 | B21: 87.09 | C21: 87.09 | H21: 110 | I21: 110 | AC21: 1 | AD21: =AC21 -> 1
A22: 蛋白质供能比 | B22: 0.83 | C22: 0.83 | F22: 0.93 | H22: 0.97 | AC22: 0.96083551 | AD22: =AC22 -> 0.96083551
A23: 脂肪供能比 | B23: 0.09 | C23: 0.09 | F23: 0.02 | H23: 0 | AC23: 0.021148825 | AD23: =AC23 -> 0.021148825
A24: 碳水化合物供能比 | B24: 0.08 | C24: 0.08 | F24: 0.03 | H24: 0.01 | AC24: 0.0031331593 | AD24: =AC24 -> 0.0031331593
A25: 乳糖 | B25: 2.2-6.8g | C25: 2.2-6.8g | AC25: 0.3 | AD25: =100*AC25/AC$9 -> 0.018726592
A26: 膳食纤维 | O26: 1 | S26: 5.2 | T26: 3.8 | X26: 5.8 | Y26: 7 | AC26: 0 | AD26: =100*AC26/AC$9 -> 0
A27: β-葡聚糖（g） | L27: 0.5
A28: 维生素A（μgRE） | P28: 650 | S28: 1120 | X28: 400 | Z28: 78 | AA28: 78
A29: 维生素D（μg） | P29: 16 | S29: 2 | W29: 1.3 | X29: 1.9 | Y29: 1.2
A30: 维生素B1（mg） | P30: 5.33 | S30: 1.73 | X30: 1.6 | Y30: 1 | Z30: 1.9 | AA30: 1.9
A31: 维生素B2（mg） | P31: 2.67 | X31: 0.9 | Y31: 0.9 | Z31: 2.12 | AA31: 2.12
A32: 维生素B6（mg） | P32: 2.67 | S32: 1.99 | V32: 0.12 | X32: 1.75 | Y32: 1 | Z32: 1.98 | AA32: 1.98
A33: 维生素B12（μg） | S33: 4.99 | T33: 2.7 | X33: 1.8 | Y33: 2
A34: 维生素C（mg） | S34: 210 | X34: 104 | Z34: 123 | AA34: 123
A35: 维生素E（mg α-TE） | S35: 13.51 | T35: 18 | Y35: 10
A36: 铁mg） | S36: 10 | X36: 18.9 | Y36: 10.6 | Z36: 16.7 | AA36: 16.7
A37: 锌（mg） | P37: 17.91 | S37: 7.24 | T37: 7.2 | X37: 13.6 | Y37: 7 | Z37: 15.85 | AA37: 15.85
A38: 牛磺酸（g） | P38: 0.1 | Y38: 110 | Z38: 127 | AA38: 127
A39: 左旋肉碱（mg） | X39: 600
A40: 烟酸（mg） | X40: 16 | Y40: 12 | Z40: 27.56 | AA40: 27.56
...
